Workbook

Sheet Brand
A1: Brand Code | B1: Brand Name | C1: Country | D1: INSERT INTO medical_supply_brand (name, country, code) VALUES ('3M', 'United States', '3M');
A2: BRAND-001 | B2: 3M™ | C2: Mỹ | D2: ="INSERT INTO medical_supply_brand (name, country, code) VALUES ('"&SUBSTITUTE(B2,"'","''")&"', '"&SUBSTITUTE(C2,"'","''")&"', '"&SUBSTITUTE(A2,"'","''")&"');" -> INSERT INTO medical_supply_brand (name, country, code) VALUES ('3M™', 'Mỹ', 'BRAND-001');
A3: BRAND-002 | B3: Abbott | C3: Mỹ | D3: ="INSERT INTO medical_supply_brand (name, country, code) VALUES ('"&SUBSTITUTE(B3,"'","''")&"', '"&SUBSTITUTE(C3,"'","''")&"', '"&SUBSTITUTE(A3,"'","''")&"');" -> INSERT INTO medical_supply_brand (name, country, code) VALUES ('Abbott', 'Mỹ', 'BRAND-002');
A4: BRAND-003 | B4: Acon | C4: Mỹ | D4: ="INSERT INTO medical_supply_brand (name, country, code) VALUES ('"&SUBSTITUTE(B4,"'","''")&"', '"&SUBSTITUTE(C4,"'","''")&"', '"&SUBSTITUTE(A4,"'","''")&"');" -> INSERT INTO medical_supply_brand (name, country, code) VALUES ('Acon', 'Mỹ', 'BRAND-003');
A5: BRAND-004 | B5: Aveflor | C5: Cộng hòa Séc | D5: ="INSERT INTO medical_supply_brand (name, country, code) VALUES ('"&SUBSTITUTE(B5,"'","''")&"', '"&SUBSTITUTE(C5,"'","''")&"', '"&SUBSTITUTE(A5,"'","''")&"');" -> INSERT INTO medical_supply_brand (name, country, code) VALUES ('Aveflor', 'Cộng hòa Séc', 'BRAND-004');
A6: BRAND-005 | B6: Bicakcilar | C6: Thổ Nhĩ Kỳ | D6: ="INSERT INTO medical_supply_brand (name, country, code) VALUES ('"&SUBSTITUTE(B6,"'","''")&"', '"&SUBSTITUTE(C6,"'","''")&"', '"&SUBSTITUTE(A6,"'","''")&"');" -> INSERT INTO medical_supply_brand (name, country, code) VALUES ('Bicakcilar', 'Thổ Nhĩ Kỳ', 'BRAND-005');
A7: BRAND-006 | B7: Biotek | C7: Trung Quốc | D7: ="INSERT INTO medical_supply_brand (name, country, code) VALUES ('"&SUBSTITUTE(B7,"'","''")&"', '"&SUBSTITUTE(C7,"'","''")&"', '"&SUBSTITUTE(A7,"'","''")&"');" -> INSERT INTO medical_supply_brand (name, country, code) VALUES ('Biotek', 'Trung Quốc', 'BRAND-006');
A8: BRAND-007 | B8: Bornsun | C8: Trung Quốc | D8: ="INSERT INTO medical_supply_brand (name, country, code) VALUES ('"&SUBSTITUTE(B8,"'","''")&"', '"&SUBSTITUTE(C8,"'","''")&"', '"&SUBSTITUTE(A8,"'","''")&"');" -> INSERT INTO medical_supply_brand (name, country, code) VALUES ('Bornsun', 'Trung Quốc', 'BRAND-007');
A9: BRAND-008 | B9: CODY | C9: Hàn Quốc | D9: ="INSERT INTO medical_supply_brand (name, country, code) VALUES ('"&SUBSTITUTE(B9,"'","''")&"', '"&SUBSTITUTE(C9,"'","''")&"', '"&SUBSTITUTE(A9,"'","''")&"');" -> INSERT INTO medical_supply_brand (name, country, code) VALUES ('CODY', 'Hàn Quốc', 'BRAND-008');
A10: BRAND-009 | B10: CODY Health | C10: Đài Loan | D10: ="INSERT INTO medical_supply_brand (name, country, code) VALUES ('"&SUBSTITUTE(B10,"'","''")&"', '"&SUBSTITUTE(C10,"'","''")&"', '"&SUBSTITUTE(A10,"'","''")&"');" -> INSERT INTO medical_supply_brand (name, country, code) VALUES ('CODY Health', 'Đài Loan', 'BRAND-009');
A11: BRAND-010 | B11: Coloplast | C11: Đan Mạch | D11: ="INSERT INTO medical_supply_brand (name, country, code) VALUES ('"&SUBSTITUTE(B11,"'","''")&"', '"&SUBSTITUTE(C11,"'","''")&"', '"&SUBSTITUTE(A11,"'","''")&"');" -> INSERT INTO medical_supply_brand (name, country, code) VALUES ('Coloplast', 'Đan Mạch', 'BRAND-010');
A12: BRAND-011 | B12: ConvaTec | C12: Cộng hòa Dominica | D12: ="INSERT INTO medical_supply_brand (name, country, code) VALUES ('"&SUBSTITUTE(B12,"'","''")&"', '"&SUBSTITUTE(C12,"'","''")&"', '"&SUBSTITUTE(A12,"'","''")&"');" -> INSERT INTO medical_supply_brand (name, country, code) VALUES ('ConvaTec', 'Cộng hòa Dominica', 'BRAND-011');
A13: BRAND-012 | B13: Covidien | C13: Mỹ | D13: ="INSERT INTO medical_supply_brand (name, country, code) VALUES ('"&SUBSTITUTE(B13,"'","''")&"', '"&SUBSTITUTE(C13,"'","''")&"', '"&SUBSTITUTE(A13,"'","''")&"');" -> INSERT INTO medical_supply_brand (name, country, code) VALUES ('Covidien', 'Mỹ', 'BRAND-012');
... A31: BRAND-030 | B31: Jumper | C31: Trung Quốc | D31: ="INSERT INTO medical_supply_brand (name, country, code) VALUES ('"&SUBSTITUTE(B31,"'","''")&"', '"&SUBSTITUTE(C31,"'","''")&"', '"&SUBSTITUTE(A31,"'","''")&"');" -> INSERT INTO medical_supply_brand (name, country, code) VALUES ('Jumper', 'Trung Quốc', 'BRAND-030');
A32: BRAND-031 | B32: Khác | D32: ="INSERT INTO medical_supply_brand (name, country, code) VALUES ('"&SUBSTITUTE(B32,"'","''")&"', '"&SUBSTITUTE(C32,"'","''")&"', '"&SUBSTITUTE(A32,"'","''")&"');" -> INSERT INTO medical_supply_brand (name, country, code) VALUES ('Khác', '', 'BRAND-031');
A33: BRAND-032 | B33: Lepu Medical | C33: Trung Quốc | D33: ="INSERT INTO medical_supply_brand (name, country, code) VALUES ('"&SUBSTITUTE(B33,"'","''")&"', '"&SUBSTITUTE(C33,"'","''")&"', '"&SUBSTITUTE(A33,"'","''")&"');" -> INSERT INTO medical_supply_brand (name, country, code) VALUES ('Lepu Medical', 'Trung Quốc', 'BRAND-032');
A34: BRAND-033 | B34: Lohmann-Rauscher | C34: Đức | D34: ="INSERT INTO medical_supply_brand (name, country, code) VALUES ('"&SUBSTITUTE(B34,"'","''")&"', '"&SUBSTITUTE(C34,"'","''")&"', '"&SUBSTITUTE(A34,"'","''")&"');" -> INSERT INTO medical_supply_brand (name, country, code) VALUES ('Lohmann-Rauscher', 'Đức', 'BRAND-033');
A35: BRAND-034 | B35: Long-term Health | C35: Trung Quốc | D35: ="INSERT INTO medical_supply_brand (name, country, code) VALUES ('"&SUBSTITUTE(B35,"'","''")&"', '"&SUBSTITUTE(C35,"'","''")&"', '"&SUBSTITUTE(A35,"'","''")&"');" -> INSERT INTO medical_supply_brand (name, country, code) VALUES ('Long-term Health', 'Trung Quốc', 'BRAND-034');
A36: BRAND-035 | B36: Lucass | C36: Mỹ | D36: ="INSERT INTO medical_supply_brand (name, country, code) VALUES ('"&SUBSTITUTE(B36,"'","''")&"', '"&SUBSTITUTE(C36,"'","''")&"', '"&SUBSTITUTE(A36,"'","''")&"');" -> INSERT INTO medical_supply_brand (name, country, code) VALUES ('Lucass', 'Mỹ', 'BRAND-035');
A37: BRAND-036 | B37: Medis Medical | C37: Trung Quốc | D37: ="INSERT INTO medical_supply_brand (name, country, code) VALUES ('"&SUBSTITUTE(B37,"'","''")&"', '"&SUBSTITUTE(C37,"'","''")&"', '"&SUBSTITUTE(A37,"'","''")&"');" -> INSERT INTO medical_supply_brand (name, country, code) VALUES ('Medis Medical', 'Trung Quốc', 'BRAND-036');
A38: BRAND-037 | B38: Meditera | C38: Thổ Nhĩ Kỳ | D38: ="INSERT INTO medical_supply_brand (name, country, code) VALUES ('"&SUBSTITUTE(B38,"'","''")&"', '"&SUBSTITUTE(C38,"'","''")&"', '"&SUBSTITUTE(A38,"'","''")&"');" -> INSERT INTO medical_supply_brand (name, country, code) VALUES ('Meditera', 'Thổ Nhĩ Kỳ', 'BRAND-037');
A39: BRAND-038 | B39: Medtronic | C39: Mỹ | D39: ="INSERT INTO medical_supply_brand (name, country, code) VALUES ('"&SUBSTITUTE(B39,"'","''")&"', '"&SUBSTITUTE(C39,"'","''")&"', '"&SUBSTITUTE(A39,"'","''")&"');" -> INSERT INTO medical_supply_brand (name, country, code) VALUES ('Medtronic', 'Mỹ', 'BRAND-038');
A40: BRAND-039 | B40: Mepro | C40: Việt Nam | D40: ="INSERT INTO medical_supply_brand (name, country, code) VALUES ('"&SUBSTITUTE(B40,"'","''")&"', '"&SUBSTITUTE(C40,"'","''")&"', '"&SUBSTITUTE(A40,"'","''")&"');" -> INSERT INTO medical_supply_brand (name, country, code) VALUES ('Mepro', 'Việt Nam', 'BRAND-039');
A41: BRAND-040 | B41: MERA | C41: Nhật Bản | D41: ="INSERT INTO medical_supply_brand (name, country, code) VALUES ('"&SUBSTITUTE(B41,"'","''")&"', '"&SUBSTITUTE(C41,"'","''")&"', '"&SUBSTITUTE(A41,"'","''")&"');" -> INSERT INTO medical_supply_brand (name, country, code) VALUES ('MERA', 'Nhật Bản', 'BRAND-040');
A42: BRAND-041 | B42: Mera Senko | C42: Nhật Bản | D42: ="INSERT INTO medical_supply_brand (name, country, code) VALUES ('"&SUBSTITUTE(B42,"'","''")&"', '"&SUBSTITUTE(C42,"'","''")&"', '"&SUBSTITUTE(A42,"'","''")&"');" -> INSERT INTO medical_supply_brand (name, country, code) VALUES ('Mera Senko', 'Nhật Bản', 'BRAND-041');
A43: BRAND-042 | B43: Merisocks | C43: Nhật Bản | D43: ="INSERT INTO medical_supply_brand (name, country, code) VALUES ('"&SUBSTITUTE(B43,"'","''")&"', '"&SUBSTITUTE(C43,"'","''")&"', '"&SUBSTITUTE(A43,"'","''")&"');" -> INSERT INTO medical_supply_brand (name, country, code) VALUES ('Merisocks', 'Nhật Bản', 'BRAND-042');
A44: BRAND-043 | B44: MiKiDo | C44: Trung Quốc | D44: ="INSERT INTO medical_supply_brand (name, country, code) VALUES ('"&SUBSTITUTE(B44,"'","''")&"', '"&SUBSTITUTE(C44,"'","''")&"', '"&SUBSTITUTE(A44,"'","''")&"');" -> INSERT INTO medical_supply_brand (name, country, code) VALUES ('MiKiDo', 'Trung Quốc', 'BRAND-043');
... A76: BRAND-075 | B76: Yuwell | C76: Trung Quốc | D76: ="INSERT INTO medical_supply_brand (name, country, code) VALUES ('"&SUBSTITUTE(B76,"'","''")&"', '"&SUBSTITUTE(C76,"'","''")&"', '"&SUBSTITUTE(A76,"'","''")&"');" -> INSERT INTO medical_supply_brand (name, country, code) VALUES ('Yuwell', 'Trung Quốc', 'BRAND-075');

Sheet Product Category
A1: Tên danh mục | B1: Mô tả
A2: Đệm chống lở loét | B2: Phao và đệm hơi giúp phân tán áp lực, phòng ngừa và hỗ trợ điều trị loét tì đè cho người nằm hoặc ngồi lâu.
A3: Máy trợ thính | B3: Thiết bị khuếch đại âm thanh cho người nghe kém, lãng tai; có loại dây đeo, móc vành tai và nhét trong tai.
A4: Máy tăm nước | B4: Máy dùng tia nước áp lực làm sạch kẽ răng, khe nướu, hỗ trợ ngừa viêm nướu, phù hợp người niềng răng, implant.
A5: Miếng dán mụn | B5: Miếng dán hydrocolloid hút dịch mủ, nhân mụn, kháng khuẩn và hạn chế thâm sẹo.
A6: Mặt nạ xông hơi mắt | B6: Mặt nạ tự sinh nhiệt giúp thư giãn mắt, giảm mỏi mắt và hỗ trợ ngủ ngon.
A7: Máy hút áp lực âm (VAC) | B7: Máy điều trị vết thương bằng áp lực âm (NPWT), hút dịch, giảm phù nề và kích thích mô hạt cho vết thương mạn tính, khó lành.
A8: Bộ gạc áp lực âm (VAC) | B8: Bộ gạc xốp phủ vết thương dùng kèm máy hút áp lực âm, có chức năng rửa và dẫn lưu dịch trong hệ thống khép kín.
A9: Miếng dán khép miệng vết thương | B9: Miếng dán thay chỉ khâu hoặc kim bấm da, khép miệng vết thương sau phẫu thuật, tiểu phẫu hoặc chấn thương.
A10: Xịt bảo vệ da | B10: Dung dịch xịt tạo màng phim bảo vệ da khỏi nước tiểu, phân, dịch tiết, ngừa hăm và loét da.
A11: Băng dán hydrocolloid | B11: Băng dán tạo môi trường ẩm cho vết thương tiết dịch ít đến trung bình, giúp mau lành, hạn chế sẹo, chống nước.
A12: Gel bôi vết thương | B12: Gel giữ ẩm, kháng khuẩn và tái tạo mô cho vết thương hở, bỏng, trầy xước, loét, vết mổ.
... A77: Khẩu trang y tế | B77: Khẩu trang y tế lọc bụi mịn, vi khuẩn (N95).

Sheet Product
A1: Mã sản phẩm | B1: Tên sản phẩm (rút gọn) | C1: Thương hiệu | D1: Danh mục | E1: Giới thiệu | F1: Brand Code | G1: UOM (Đơn vị tính) | H1: INSERT INTO medical_supply_product (id, active, category, description, name, sub_category, code, brand_code) VALUES (269, true, 'dasd', 'asdasd', 'asdasd', 'asdasd', 'asdasd', 'IMEDICARE');
A2: PRODUCT-00001 | B2: [Greetmed] Phao chống loét cao su | C2: Greetmed | D2: Đệm chống lở loét | E2: Phao chống loét cao su Greetmed (Ø30cm, van đồng) nâng đỡ và phân tán áp lực lên vùng mông, hông, lưng, giúp phòng ngừa và hỗ trợ điều trị loét tì đè. Phù hợp cho người phải nằm hoặc ngồi lâu, dùng tại nhà hoặc cơ sở y tế. | F2: =IFERROR(INDEX(Brand!$A:$A,MATCH(TRIM(C2),Brand!$B:$B,0)),"NOT FOUND") -> BRAND-020 | G2: cái | H2: ="INSERT INTO medical_supply_product (active, category, description, name, code, brand_code, uom) VALUES (true, '"&SUBSTITUTE(D2,"'","''")&"', '"&SUBSTITUTE(E2,"'","''")&"', '"&SUBSTITUTE(B2,"'","''")&"', '"&SUBSTITUTE(A2,"'","''")&"', '"&SUBSTITUTE(F2,"'","''")&"', '"&SUBSTITUTE(G2,"'","''")&"');" -> INSERT INTO medical_supply_product (active, category, description, name, code, brand_code, uom) VALUES (true, 'Đệm chống lở loét', 'Phao chống loét cao su Greetmed (Ø30cm, van đồng) nâng đỡ và phân tán áp lực lên vùng mông, hông, lưng, giúp phòng ngừa và hỗ trợ điều trị loét tì đè. Phù hợp cho người phải nằm hoặc ngồi lâu, dùng tại nhà hoặc cơ sở y tế.', '[Greetmed] Phao chống loét cao su', 'PRODUCT-00001', 'BRAND-020', 'cái');
A3: PRODUCT-00002 | B3: [iMedicare] Đệm hơi chống lở loét - iAM-8P | C3: iMedicare | D3: Đệm chống lở loét | E3: Đệm hơi chống lở loét iMedicare iAM-8P giúp phòng ngừa và hỗ trợ điều trị lở loét cho người nằm lâu như bệnh nhân liệt, bỏng, gãy xương, sau phẫu thuật, người cao tuổi. Bơm điện chạy êm, đệm dễ gấp gọn, vệ sinh; đạt tiêu chuẩn CE. | F3: =IFERROR(INDEX(Brand!$A:$A,MATCH(TRIM(C3),Brand!$B:$B,0)),"NOT FOUND") -> BRAND-028 | G3: bộ | H3: ="INSERT INTO medical_supply_product (active, category, description, name, code, brand_code, uom) VALUES (true, '"&SUBSTITUTE(D3,"'","''")&"', '"&SUBSTITUTE(E3,"'","''")&"', '"&SUBSTITUTE(B3,"'","''")&"', '"&SUBSTITUTE(A3,"'","''")&"', '"&SUBSTITUTE(F3,"'","''")&"', '"&SUBSTITUTE(G3,"'","''")&"');" -> INSERT INTO medical_supply_product (active, category, description, name, code, brand_code, uom) VALUES (true, 'Đệm chống lở loét', 'Đệm hơi chống lở loét iMedicare iAM-8P giúp phòng ngừa và hỗ trợ điều trị lở loét cho người nằm lâu như bệnh nhân liệt, bỏng, gãy xương, sau phẫu thuật, người cao tuổi. Bơm điện chạy êm, đệm dễ gấp gọn, vệ sinh; đạt tiêu chuẩn CE.', '[iMedicare] Đệm hơi chống lở loét - iAM-8P', 'PRODUCT-00002', 'BRAND-028', 'bộ');
A4: PRODUCT-00003 | B4: [Lucass] Đệm hơi chống lở loét - LC-389 | C4: Lucass | D4: Đệm chống lở loét | E4: Đệm hơi chống lở loét Lucass LC-389 giúp phòng ngừa và hỗ trợ điều trị lở loét cho người nằm lâu như bệnh nhân liệt, bỏng, gãy xương, sau phẫu thuật, người cao tuổi. Bơm điện chạy êm, đệm dễ di chuyển, gấp gọn và vệ sinh. | F4: =IFERROR(INDEX(Brand!$A:$A,MATCH(TRIM(C4),Brand!$B:$B,0)),"NOT FOUND") -> BRAND-035 | G4: bộ | H4: ="INSERT INTO medical_supply_product (active, category, description, name, code, brand_code, uom) VALUES (true, '"&SUBSTITUTE(D4,"'","''")&"', '"&SUBSTITUTE(E4,"'","''")&"', '"&SUBSTITUTE(B4,"'","''")&"', '"&SUBSTITUTE(A4,"'","''")&"', '"&SUBSTITUTE(F4,"'","''")&"', '"&SUBSTITUTE(G4,"'","''")&"');" -> INSERT INTO medical_supply_product (active, category, description, name, code, brand_code, uom) VALUES (true, 'Đệm chống lở loét', 'Đệm hơi chống lở loét Lucass LC-389 giúp phòng ngừa và hỗ trợ điều trị lở loét cho người nằm lâu như bệnh nhân liệt, bỏng, gãy xương, sau phẫu thuật, người cao tuổi. Bơm điện chạy êm, đệm dễ di chuyển, gấp gọn và vệ sinh.', '[Lucass] Đệm hơi chống lở loét - LC-389', 'PRODUCT-00003', 'BRAND-035', 'bộ');
A5: PRODUCT-00004 | B5: [Rionet] Máy trợ thính có dây đeo - HA-20DX | C5: Rionet | D5: Máy trợ thính | E5: Máy trợ thính có dây Rionet HA-20DX khuếch đại âm thanh cho người nghe kém, lãng tai, đặc biệt là người cao tuổi. Nút bấm lớn dễ dùng, 10 mức âm lượng, 3 chế độ âm thanh có lọc tạp âm, dùng pin AA. | F5: =IFERROR(INDEX(Brand!$A:$A,MATCH(TRIM(C5),Brand!$B:$B,0)),"NOT FOUND") -> BRAND-052 | G5: cái | H5: ="INSERT INTO medical_supply_product (active, category, description, name, code, brand_code, uom) VALUES (true, '"&SUBSTITUTE(D5,"'","''")&"', '"&SUBSTITUTE(E5,"'","''")&"', '"&SUBSTITUTE(B5,"'","''")&"', '"&SUBSTITUTE(A5,"'","''")&"', '"&SUBSTITUTE(F5,"'","''")&"', '"&SUBSTITUTE(G5,"'","''")&"');" -> INSERT INTO medical_supply_product (active, category, description, name, code, brand_code, uom) VALUES (true, 'Máy trợ thính', 'Máy trợ thính có dây Rionet HA-20DX khuếch đại âm thanh cho người nghe kém, lãng tai, đặc biệt là người cao tuổi. Nút bấm lớn dễ dùng, 10 mức âm lượng, 3 chế độ âm thanh có lọc tạp âm, dùng pin AA.', '[Rionet] Máy trợ thính có dây đeo - HA-20DX', 'PRODUCT-00004', 'BRAND-052', 'cái');
A6: PRODUCT-00005 | B6: [Rionet] Máy trợ thính không dây - HB-23P | C6: Rionet | D6: Máy trợ thính | E6: Máy trợ thính không dây Rionet HB-23P dạng móc vành tai, màu da kín đáo, hỗ trợ người lãng tai, nghe kém ở mọi lứa tuổi. Âm thanh rõ, có lọc ồn, chỉ 2 nút điều khiển nên dễ sử dụng. | F6: =IFERROR(INDEX(Brand!$A:$A,MATCH(TRIM(C6),Brand!$B:$B,0)),"NOT FOUND") -> BRAND-052 | G6: cái | H6: ="INSERT INTO medical_supply_product (active, category, description, name, code, brand_code, uom) VALUES (true, '"&SUBSTITUTE(D6,"'","''")&"', '"&SUBSTITUTE(E6,"'","''")&"', '"&SUBSTITUTE(B6,"'","''")&"', '"&SUBSTITUTE(A6,"'","''")&"', '"&SUBSTITUTE(F6,"'","''")&"', '"&SUBSTITUTE(G6,"'","''")&"');" -> INSERT INTO medical_supply_product (active, category, description, name, code, brand_code, uom) VALUES (true, 'Máy trợ thính', 'Máy trợ thính không dây Rionet HB-23P dạng móc vành tai, màu da kín đáo, hỗ trợ người lãng tai, nghe kém ở mọi lứa tuổi. Âm thanh rõ, có lọc ồn, chỉ 2 nút điều khiển nên dễ sử dụng.', '[Rionet] Máy trợ thính không dây - HB-23P', 'PRODUCT-00005', 'BRAND-052', 'cái');
A7: PRODUCT-00006 | B7: [Rionet] Máy trợ thính không dây thông minh - HM-06 | C7: Rionet | D7: Máy trợ thính | E7: Máy trợ thính kỹ thuật số Rionet HM-06 siêu nhỏ, đeo trong tai kín đáo và thoải mái khi đeo lâu. Lọc âm và giảm ồn hiệu quả, âm thanh tự nhiên; phù hợp người trẻ, trung niên, dân văn phòng. | F7: =IFERROR(INDEX(Brand!$A:$A,MATCH(TRIM(C7),Brand!$B:$B,0)),"NOT FOUND") -> BRAND-052 | G7: cái | H7: ="INSERT INTO medical_supply_product (active, category, description, name, code, brand_code, uom) VALUES (true, '"&SUBSTITUTE(D7,"'","''")&"', '"&SUBSTITUTE(E7,"'","''")&"', '"&SUBSTITUTE(B7,"'","''")&"', '"&SUBSTITUTE(A7,"'","''")&"', '"&SUBSTITUTE(F7,"'","''")&"', '"&SUBSTITUTE(G7,"'","''")&"');" -> INSERT INTO medical_supply_product (active, category, description, name, code, brand_code, uom) VALUES (true, 'Máy trợ thính', 'Máy trợ thính kỹ thuật số Rionet HM-06 siêu nhỏ, đeo trong tai kín đáo và thoải mái khi đeo lâu. Lọc âm và giảm ồn hiệu quả, âm thanh tự nhiên; phù hợp người trẻ, trung niên, dân văn phòng.', '[Rionet] Máy trợ thính không dây thông minh - HM-06', 'PRODUCT-00006', 'BRAND-052', 'cái');
A8: PRODUCT-00007 | B8: [WaterJet] Máy tăm nước - Cordless Maxi | C8: WaterJet | D8: Máy tăm nước | E8: Máy tăm nước không dây WaterJet Cordless Maxi làm sạch kẽ răng, khe nướu và vùng khó chải, giúp ngừa viêm nướu. Áp lực 40–90 PSI với 4 chế độ, bình chứa lớn; phù hợp người niềng răng, implant, bọc sứ, nướu nhạy cảm. | F8: =IFERROR(INDEX(Brand!$A:$A,MATCH(TRIM(C8),Brand!$B:$B,0)),"NOT FOUND") -> BRAND-069 | G8: cái | H8: ="INSERT INTO medical_supply_product (active, category, description, name, code, brand_code, uom) VALUES (true, '"&SUBSTITUTE(D8,"'","''")&"', '"&SUBSTITUTE(E8,"'","''")&"', '"&SUBSTITUTE(B8,"'","''")&"', '"&SUBSTITUTE(A8,"'","''")&"', '"&SUBSTITUTE(F8,"'","''")&"', '"&SUBSTITUTE(G8,"'","''")&"');" -> INSERT INTO medical_supply_product (active, category, description, name, code, brand_code, uom) VALUES (true, 'Máy tăm nước', 'Máy tăm nước không dây WaterJet Cordless Maxi làm sạch kẽ răng, khe nướu và vùng khó chải, giúp ngừa viêm nướu. Áp lực 40–90 PSI với 4 chế độ, bình chứa lớn; phù hợp người niềng răng, implant, bọc sứ, nướu nhạy cảm.', '[WaterJet] Máy tăm nước - Cordless Maxi', 'PRODUCT-00007', 'BRAND-069', 'cái');
A9: PRODUCT-00008 | B9: [Young Chemical Vina] Miếng dán mụn - Somaderm Spot S (32 miếng) | C9: Young Chemical Vina | D9: Miếng dán mụn | E9: Miếng dán mụn Somaderm Spot chứa hydrocolloid giúp hút dịch mủ, nhân mụn, kháng khuẩn và hạn chế sẹo thâm. Miếng tròn nhỏ, cùng màu da, chống nước, dùng được cho mọi loại da. | F9: =IFERROR(INDEX(Brand!$A:$A,MATCH(TRIM(C9),Brand!$B:$B,0)),"NOT FOUND") -> BRAND-073 | G9: miếng | H9: ="INSERT INTO medical_supply_product (active, category, description, name, code, brand_code, uom) VALUES (true, '"&SUBSTITUTE(D9,"'","''")&"', '"&SUBSTITUTE(E9,"'","''")&"', '"&SUBSTITUTE(B9,"'","''")&"', '"&SUBSTITUTE(A9,"'","''")&"', '"&SUBSTITUTE(F9,"'","''")&"', '"&SUBSTITUTE(G9,"'","''")&"');" -> INSERT INTO medical_supply_product (active, category, description, name, code, brand_code, uom) VALUES (true, 'Miếng dán mụn', 'Miếng dán mụn Somaderm Spot chứa hydrocolloid giúp hút dịch mủ, nhân mụn, kháng khuẩn và hạn chế sẹo thâm. Miếng tròn nhỏ, cùng màu da, chống nước, dùng được cho mọi loại da.', '[Young Chemical Vina] Miếng dán mụn - Somaderm Spot S (32 miếng)', 'PRODUCT-00008', 'BRAND-073', 'miếng');
A10: PRODUCT-00009 | B10: [Young Chemical Vina] Miếng dán mụn - Somaderm-Thin (Ø10mm) | C10: Young Chemical Vina | D10: Miếng dán mụn | E10: Miếng dán mụn Somaderm-Thin chứa hydrocolloid giúp hút dịch mủ, nhân mụn, giữ ẩm và hạn chế thâm sẹo. Miếng tròn siêu mỏng, cùng màu da, ít kích ứng, dùng được cho da nhạy cảm. | F10: =IFERROR(INDEX(Brand!$A:$A,MATCH(TRIM(C10),Brand!$B:$B,0)),"NOT FOUND") -> BRAND-073 | G10: miếng | H10: ="INSERT INTO medical_supply_product (active, category, description, name, code, brand_code, uom) VALUES (true, '"&SUBSTITUTE(D10,"'","''")&"', '"&SUBSTITUTE(E10,"'","''")&"', '"&SUBSTITUTE(B10,"'","''")&"', '"&SUBSTITUTE(A10,"'","''")&"', '"&SUBSTITUTE(F10,"'","''")&"', '"&SUBSTITUTE(G10,"'","''")&"');" -> INSERT INTO medical_supply_product (active, category, description, name, code, brand_code, uom) VALUES (true, 'Miếng dán mụn', 'Miếng dán mụn Somaderm-Thin chứa hydrocolloid giúp hút dịch mủ, nhân mụn, giữ ẩm và hạn chế thâm sẹo. Miếng tròn siêu mỏng, cùng màu da, ít kích ứng, dùng được cho da nhạy cảm.', '[Young Chemical Vina] Miếng dán mụn - Somaderm-Thin (Ø10mm)', 'PRODUCT-00009', 'BRAND-073', 'miếng');
A11: PRODUCT-00010 | B11: Mặt nạ xông hơi mắt ngải cứu - Mugwort Steam Eyes Mask | C11: Khác | D11: Mặt nạ xông hơi mắt | E11: Mặt nạ xông hơi mắt ngải cứu tự sinh nhiệt khoảng 40°C khi mở, giúp thư giãn mắt, giảm mỏi mắt và quầng thâm, hỗ trợ ngủ ngon. Phù hợp người thường dùng máy tính, đọc sách, thức khuya, mất ngủ. | F11: =IFERROR(INDEX(Brand!$A:$A,MATCH(TRIM(C11),Brand!$B:$B,0)),"NOT FOUND") -> BRAND-031 | G11: miếng | H11: ="INSERT INTO medical_supply_product (active, category, description, name, code, brand_code, uom) VALUES (true, '"&SUBSTITUTE(D11,"'","''")&"', '"&SUBSTITUTE(E11,"'","''")&"', '"&SUBSTITUTE(B11,"'","''")&"', '"&SUBSTITUTE(A11,"'","''")&"', '"&SUBSTITUTE(F11,"'","''")&"', '"&SUBSTITUTE(G11,"'","''")&"');" -> INSERT INTO medical_supply_product (active, category, description, name, code, brand_code, uom) VALUES (true, 'Mặt nạ xông hơi mắt', 'Mặt nạ xông hơi mắt ngải cứu tự sinh nhiệt khoảng 40°C khi mở, giúp thư giãn mắt, giảm mỏi mắt và quầng thâm, hỗ trợ ngủ ngon. Phù hợp người thường dùng máy tính, đọc sách, thức khuya, mất ngủ.', 'Mặt nạ xông hơi mắt ngải cứu - Mugwort Steam Eyes Mask', 'PRODUCT-00010', 'BRAND-031', 'miếng');
A12: PRODUCT-00011 | B12: [3M™] Bộ gạc xốp phủ vết thương điều trị áp lực âm VAC kèm chức năng rửa - Veraflo™ | C12: 3M™ | D12: Bộ gạc áp lực âm (VAC) | E12: Bộ gạc xốp 3M™ Veraflo™ dùng kèm máy hút áp lực âm VAC có chức năng rửa, điều trị vết thương mạn tính, khó lành. Hệ thống khép kín giúp rửa, dẫn lưu dịch, giữ ẩm và kích thích mô hạt phát triển. | F12: =IFERROR(INDEX(Brand!$A:$A,MATCH(TRIM(C12),Brand!$B:$B,0)),"NOT FOUND") -> BRAND-001 | G12: bộ | H12: ="INSERT INTO medical_supply_product (active, category, description, name, code, brand_code, uom) VALUES (true, '"&SUBSTITUTE(D12,"'","''")&"', '"&SUBSTITUTE(E12,"'","''")&"', '"&SUBSTITUTE(B12,"'","''")&"', '"&SUBSTITUTE(A12,"'","''")&"', '"&SUBSTITUTE(F12,"'","''")&"', '"&SUBSTITUTE(G12,"'","''")&"');" -> INSERT INTO medical_supply_product (active, category, description, name, code, brand_code, uom) VALUES (true, 'Bộ gạc áp lực âm (VAC)', 'Bộ gạc xốp 3M™ Veraflo™ dùng kèm máy hút áp lực âm VAC có chức năng rửa, điều trị vết thương mạn tính, khó lành. Hệ thống khép kín giúp rửa, dẫn lưu dịch, giữ ẩm và kích thích mô hạt phát triển.', '[3M™] Bộ gạc xốp phủ vết thương điều trị áp lực âm VAC kèm chức năng rửa - Veraflo™', 'PRODUCT-00011', 'BRAND-001', 'bộ');
A13: PRODUCT-00012 | B13: [3M™] Miếng dán vết thương thay chỉ khâu - STERI-STRIP™ (3mmx75mm) | C13: 3M™ | D13: Miếng dán khép miệng vết thương | E13: Miếng dán 3M™ Steri-Strip™ thay chỉ khâu hoặc kim bấm da, giúp khép miệng vết thương sau phẫu thuật, tiểu phẫu hoặc vết rách do chấn thương. Không xâm lấn, thao tác dễ, hạn chế giãn sẹo. | F13: =IFERROR(INDEX(Brand!$A:$A,MATCH(TRIM(C13),Brand!$B:$B,0)),"NOT FOUND") -> BRAND-001 | G13: sợi | H13: ="INSERT INTO medical_supply_product (active, category, description, name, code, brand_code, uom) VALUES (true, '"&SUBSTITUTE(D13,"'","''")&"', '"&SUBSTITUTE(E13,"'","''")&"', '"&SUBSTITUTE(B13,"'","''")&"', '"&SUBSTITUTE(A13,"'","''")&"', '"&SUBSTITUTE(F13,"'","''")&"', '"&SUBSTITUTE(G13,"'","''")&"');" -> INSERT INTO medical_supply_product (active, category, description, name, code, brand_code, uom) VALUES (true, 'Miếng dán khép miệng vết thương', 'Miếng dán 3M™ Steri-Strip™ thay chỉ khâu hoặc kim bấm da, giúp khép miệng vết thương sau phẫu thuật, tiểu phẫu hoặc vết rách do chấn thương. Không xâm lấn, thao tác dễ, hạn chế giãn sẹo.', '[3M™] Miếng dán vết thương thay chỉ khâu - STERI-STRIP™ (3mmx75mm)', 'PRODUCT-00012', 'BRAND-001', 'sợi');
... A219: PRODUCT-00218 | B219: [Bornsun] Hệ thống dẫn lưu phân | C219: Bornsun | D219: Hệ thống dẫn lưu phân | E219: Hệ thống dẫn lưu phân Bornsun bằng gel silica y tế, thu gom phân lỏng, bán lỏng cho bệnh nhân nằm lâu, đặc biệt tại ICU. Bảo vệ da quanh hậu môn, ngừa nhiễm trùng và giảm công chăm sóc; dùng 1 lần. | F219: =IFERROR(INDEX(Brand!$A:$A,MATCH(TRIM(C219),Brand!$B:$B,0)),"NOT FOUND") -> BRAND-007 | G219: bộ | H219: ="INSERT INTO medical_supply_product (active, category, description, name, code, brand_code, uom) VALUES (true, '"&SUBSTITUTE(D219,"'","''")&"', '"&SUBSTITUTE(E219,"'","''")&"', '"&SUBSTITUTE(B219,"'","''")&"', '"&SUBSTITUTE(A219,"'","''")&"', '"&SUBSTITUTE(F219,"'","''")&"', '"&SUBSTITUTE(G219,"'","''")&"');" -> INSERT INTO medical_supply_product (active, category, description, name, code, brand_code, uom) VALUES (true, 'Hệ thống dẫn lưu phân', 'Hệ thống dẫn lưu phân Bornsun bằng gel silica y tế, thu gom phân lỏng, bán lỏng cho bệnh nhân nằm lâu, đặc biệt tại ICU. Bảo vệ da quanh hậu môn, ngừa nhiễm trùng và giảm công chăm sóc; dùng 1 lần.', '[Bornsun] Hệ thống dẫn lưu phân', 'PRODUCT-00218', 'BRAND-007', 'bộ');
A220: PRODUCT-00219 | B220: [Covidien] Máy bơm thức ăn - Kangaroo ePump™ | C220: Covidien | D220: Máy bơm thức ăn | F220: =IFERROR(INDEX(Brand!$A:$A,MATCH(TRIM(C220),Brand!$B:$B,0)),"NOT FOUND") -> BRAND-012 | G220: cái | H220: ="INSERT INTO medical_supply_product (active, category, description, name, code, brand_code, uom) VALUES (true, '"&SUBSTITUTE(D220,"'","''")&"', '"&SUBSTITUTE(E220,"'","''")&"', '"&SUBSTITUTE(B220,"'","''")&"', '"&SUBSTITUTE(A220,"'","''")&"', '"&SUBSTITUTE(F220,"'","''")&"', '"&SUBSTITUTE(G220,"'","''")&"');" -> INSERT INTO medical_supply_product (active, category, description, name, code, brand_code, uom) VALUES (true, 'Máy bơm thức ăn', '', '[Covidien] Máy bơm thức ăn - Kangaroo ePump™', 'PRODUCT-00219', 'BRAND-012', 'cái');
A221: PRODUCT-00220 | B221: [Covidien] Ống thông dạ dày nuôi ăn 29 ngày - Kangaroo | C221: Covidien | D221: Ống thông nuôi ăn | E221: Ống thông dạ dày silicone Kangaroo lưu ống đến 29 ngày, dùng đưa dinh dưỡng, thuốc vào dạ dày hoặc rửa, giảm áp dạ dày. Ít phải thay ống, giảm tổn thương mũi họng. | F221: =IFERROR(INDEX(Brand!$A:$A,MATCH(TRIM(C221),Brand!$B:$B,0)),"NOT FOUND") -> BRAND-012 | G221: cái | H221: ="INSERT INTO medical_supply_product (active, category, description, name, code, brand_code, uom) VALUES (true, '"&SUBSTITUTE(D221,"'","''")&"', '"&SUBSTITUTE(E221,"'","''")&"', '"&SUBSTITUTE(B221,"'","''")&"', '"&SUBSTITUTE(A221,"'","''")&"', '"&SUBSTITUTE(F221,"'","''")&"', '"&SUBSTITUTE(G221,"'","''")&"');" -> INSERT INTO medical_supply_product (active, category, description, name, code, brand_code, uom) VALUES (true, 'Ống thông nuôi ăn', 'Ống thông dạ dày silicone Kangaroo lưu ống đến 29 ngày, dùng đưa dinh dưỡng, thuốc vào dạ dày hoặc rửa, giảm áp dạ dày. Ít phải thay ống, giảm tổn thương mũi họng.', '[Covidien] Ống thông dạ dày nuôi ăn 29 ngày - Kangaroo', 'PRODUCT-00220', 'BRAND-012', 'cái');
A222: PRODUCT-00221 | B222: [Create Medic] Bộ mở thông dạ dày qua da - Cliny | C222: Create Medic | D222: Bộ mở thông dạ dày qua da | E222: Bộ mở thông dạ dày qua da Cliny bằng 100% silicone y tế, không latex, nuôi ăn qua thành bụng cho người tắc nghẽn tiêu hóa, tai biến, chấn thương đầu cổ. Ống 2 nòng: cổng bơm thức ăn có nắp và cổng van bơm bóng cố định. | F222: =IFERROR(INDEX(Brand!$A:$A,MATCH(TRIM(C222),Brand!$B:$B,0)),"NOT FOUND") -> BRAND-013 | G222: cái | H222: ="INSERT INTO medical_supply_product (active, category, description, name, code, brand_code, uom) VALUES (true, '"&SUBSTITUTE(D222,"'","''")&"', '"&SUBSTITUTE(E222,"'","''")&"', '"&SUBSTITUTE(B222,"'","''")&"', '"&SUBSTITUTE(A222,"'","''")&"', '"&SUBSTITUTE(F222,"'","''")&"', '"&SUBSTITUTE(G222,"'","''")&"');" -> INSERT INTO medical_supply_product (active, category, description, name, code, brand_code, uom) VALUES (true, 'Bộ mở thông dạ dày qua da', 'Bộ mở thông dạ dày qua da Cliny bằng 100% silicone y tế, không latex, nuôi ăn qua thành bụng cho người tắc nghẽn tiêu hóa, tai biến, chấn thương đầu cổ. Ống 2 nòng: cổng bơm thức ăn có nắp và cổng van bơm bóng cố định.', '[Create Medic] Bộ mở thông dạ dày qua da - Cliny', 'PRODUCT-00221', 'BRAND-013', 'cái');
A223: PRODUCT-00222 | B223: [Daesang Wellife] Sữa dinh dưỡng dành cho người tiểu đường - Nucare Glucose Plan (200ml) | C223: Daesang Wellife | D223: Sữa dinh dưỡng | E223: Sữa NUCARE Glucose Plan dinh dưỡng cân bằng dành riêng cho người tiểu đường, giúp kiểm soát đường huyết sau ăn. Dùng thay bữa chính hoặc bữa phụ; hương vị dễ uống. | F223: =IFERROR(INDEX(Brand!$A:$A,MATCH(TRIM(C223),Brand!$B:$B,0)),"NOT FOUND") -> BRAND-014 | G223: hộp | H223: ="INSERT INTO medical_supply_product (active, category, description, name, code, brand_code, uom) VALUES (true, '"&SUBSTITUTE(D223,"'","''")&"', '"&SUBSTITUTE(E223,"'","''")&"', '"&SUBSTITUTE(B223,"'","''")&"', '"&SUBSTITUTE(A223,"'","''")&"', '"&SUBSTITUTE(F223,"'","''")&"', '"&SUBSTITUTE(G223,"'","''")&"');" -> INSERT INTO medical_supply_product (active, category, description, name, code, brand_code, uom) VALUES (true, 'Sữa dinh dưỡng', 'Sữa NUCARE Glucose Plan dinh dưỡng cân bằng dành riêng cho người tiểu đường, giúp kiểm soát đường huyết sau ăn. Dùng thay bữa chính hoặc bữa phụ; hương vị dễ uống.', '[Daesang Wellife] Sữa dinh dưỡng dành cho người tiểu đường - Nucare Glucose Plan (200ml)', 'PRODUCT-00222', 'BRAND-014', 'hộp');
A224: PRODUCT-00223 | B224: [Fortune] Bộ mở thông dạ dày qua da | C224: Fortune | D224: Bộ mở thông dạ dày qua da | E224: Bộ mở thông dạ dày qua da Fortune bằng silicone, nuôi ăn qua thành bụng tạm thời hoặc lâu dài. Ống 3 nòng: cổng bơm thức ăn, cổng bơm thuốc và cổng van bơm bóng cố định. | F224: =IFERROR(INDEX(Brand!$A:$A,MATCH(TRIM(C224),Brand!$B:$B,0)),"NOT FOUND") -> BRAND-016 | G224: cái | H224: ="INSERT INTO medical_supply_product (active, category, description, name, code, brand_code, uom) VALUES (true, '"&SUBSTITUTE(D224,"'","''")&"', '"&SUBSTITUTE(E224,"'","''")&"', '"&SUBSTITUTE(B224,"'","''")&"', '"&SUBSTITUTE(A224,"'","''")&"', '"&SUBSTITUTE(F224,"'","''")&"', '"&SUBSTITUTE(G224,"'","''")&"');" -> INSERT INTO medical_supply_product (active, category, description, name, code, brand_code, uom) VALUES (true, 'Bộ mở thông dạ dày qua da', 'Bộ mở thông dạ dày qua da Fortune bằng silicone, nuôi ăn qua thành bụng tạm thời hoặc lâu dài. Ống 3 nòng: cổng bơm thức ăn, cổng bơm thuốc và cổng van bơm bóng cố định.', '[Fortune] Bộ mở thông dạ dày qua da', 'PRODUCT-00223', 'BRAND-016', 'cái');
A225: PRODUCT-00224 | B225: [Fortune] Xông nuôi ăn silicone dài ngày | C225: Fortune | D225: Ống thông nuôi ăn | E225: Xông nuôi ăn silicone Fortune lưu ống đến 29 ngày, dùng đưa dinh dưỡng, thuốc vào dạ dày hoặc rửa, giảm áp dạ dày. Ít phải thay ống, giảm tổn thương mũi họng; tiệt trùng EO. | F225: =IFERROR(INDEX(Brand!$A:$A,MATCH(TRIM(C225),Brand!$B:$B,0)),"NOT FOUND") -> BRAND-016 | G225: cái | H225: ="INSERT INTO medical_supply_product (active, category, description, name, code, brand_code, uom) VALUES (true, '"&SUBSTITUTE(D225,"'","''")&"', '"&SUBSTITUTE(E225,"'","''")&"', '"&SUBSTITUTE(B225,"'","''")&"', '"&SUBSTITUTE(A225,"'","''")&"', '"&SUBSTITUTE(F225,"'","''")&"', '"&SUBSTITUTE(G225,"'","''")&"');" -> INSERT INTO medical_supply_product (active, category, description, name, code, brand_code, uom) VALUES (true, 'Ống thông nuôi ăn', 'Xông nuôi ăn silicone Fortune lưu ống đến 29 ngày, dùng đưa dinh dưỡng, thuốc vào dạ dày hoặc rửa, giảm áp dạ dày. Ít phải thay ống, giảm tổn thương mũi họng; tiệt trùng EO.', '[Fortune] Xông nuôi ăn silicone dài ngày', 'PRODUCT-00224', 'BRAND-016', 'cái');
A226: PRODUCT-00225 | B226: [Mepro] Dây xông dạ dày nuôi ăn silicone 30 ngày | C226: Mepro | D226: Ống thông nuôi ăn | E226: Dây xông dạ dày silicone Mepro (1200mm) lưu ống đến 30 ngày, dùng đưa dinh dưỡng, thuốc vào dạ dày hoặc hút dịch giảm áp. Ít phải thay ống, giảm tổn thương mũi họng; tiệt trùng EO. | F226: =IFERROR(INDEX(Brand!$A:$A,MATCH(TRIM(C226),Brand!$B:$B,0)),"NOT FOUND") -> BRAND-039 | G226: cái | H226: ="INSERT INTO medical_supply_product (active, category, description, name, code, brand_code, uom) VALUES (true, '"&SUBSTITUTE(D226,"'","''")&"', '"&SUBSTITUTE(E226,"'","''")&"', '"&SUBSTITUTE(B226,"'","''")&"', '"&SUBSTITUTE(A226,"'","''")&"', '"&SUBSTITUTE(F226,"'","''")&"', '"&SUBSTITUTE(G226,"'","''")&"');" -> INSERT INTO medical_supply_product (active, category, description, name, code, brand_code, uom) VALUES (true, 'Ống thông nuôi ăn', 'Dây xông dạ dày silicone Mepro (1200mm) lưu ống đến 30 ngày, dùng đưa dinh dưỡng, thuốc vào dạ dày hoặc hút dịch giảm áp. Ít phải thay ống, giảm tổn thương mũi họng; tiệt trùng EO.', '[Mepro] Dây xông dạ dày nuôi ăn silicone 30 ngày', 'PRODUCT-00225', 'BRAND-039', 'cái');
A227: PRODUCT-00226 | B227: [Nutricia] Sữa dinh dưỡng - Fortimel Power (335g) | C227: Nutricia | D227: Sữa dinh dưỡng | E227: Sữa Fortimel Power (Nutricia) giàu đạm, cao hơn 35% so với các sản phẩm thông thường, giúp người bệnh phục hồi nhanh. Phù hợp người sau mổ, người cao tuổi, người ốm cần bổ sung dinh dưỡng; dễ uống. | F227: =IFERROR(INDEX(Brand!$A:$A,MATCH(TRIM(C227),Brand!$B:$B,0)),"NOT FOUND") -> BRAND-044 | G227: hộp | H227: ="INSERT INTO medical_supply_product (active, category, description, name, code, brand_code, uom) VALUES (true, '"&SUBSTITUTE(D227,"'","''")&"', '"&SUBSTITUTE(E227,"'","''")&"', '"&SUBSTITUTE(B227,"'","''")&"', '"&SUBSTITUTE(A227,"'","''")&"', '"&SUBSTITUTE(F227,"'","''")&"', '"&SUBSTITUTE(G227,"'","''")&"');" -> INSERT INTO medical_supply_product (active, category, description, name, code, brand_code, uom) VALUES (true, 'Sữa dinh dưỡng', 'Sữa Fortimel Power (Nutricia) giàu đạm, cao hơn 35% so với các sản phẩm thông thường, giúp người bệnh phục hồi nhanh. Phù hợp người sau mổ, người cao tuổi, người ốm cần bổ sung dinh dưỡng; dễ uống.', '[Nutricia] Sữa dinh dưỡng - Fortimel Power (335g)', 'PRODUCT-00226', 'BRAND-044', 'hộp');
A228: PRODUCT-00227 | B228: [Nutricia] Sữa dinh dưỡng dành cho bệnh nhân ung thư - Forticare (125ml) | C228: Nutricia | D228: Sữa dinh dưỡng | E228: Sữa Forticare (Nutricia) dinh dưỡng chuyên biệt cho bệnh nhân ung thư, giúp ngăn ngừa và hỗ trợ điều trị sụt cân. Bổ sung năng lượng, vitamin, khoáng chất cho người suy kiệt, khó nhai nuốt, mới ốm dậy. | F228: =IFERROR(INDEX(Brand!$A:$A,MATCH(TRIM(C228),Brand!$B:$B,0)),"NOT FOUND") -> BRAND-044 | G228: chai | H228: ="INSERT INTO medical_supply_product (active, category, description, name, code, brand_code, uom) VALUES (true, '"&SUBSTITUTE(D228,"'","''")&"', '"&SUBSTITUTE(E228,"'","''")&"', '"&SUBSTITUTE(B228,"'","''")&"', '"&SUBSTITUTE(A228,"'","''")&"', '"&SUBSTITUTE(F228,"'","''")&"', '"&SUBSTITUTE(G228,"'","''")&"');" -> INSERT INTO medical_supply_product (active, category, description, name, code, brand_code, uom) VALUES (true, 'Sữa dinh dưỡng', 'Sữa Forticare (Nutricia) dinh dưỡng chuyên biệt cho bệnh nhân ung thư, giúp ngăn ngừa và hỗ trợ điều trị sụt cân. Bổ sung năng lượng, vitamin, khoáng chất cho người suy kiệt, khó nhai nuốt, mới ốm dậy.', '[Nutricia] Sữa dinh dưỡng dành cho bệnh nhân ung thư - Forticare (125ml)', 'PRODUCT-00227', 'BRAND-044', 'chai');
A229: PRODUCT-00228 | B229: [Nutricia] Sữa dinh dưỡng nuôi ăn qua ống thông - Nutrison (1000ml) | C229: Nutricia | D229: Sữa dinh dưỡng | E229: Sữa Nutrison (Nutricia) dạng nước dùng nuôi ăn qua ống thông dạ dày, cung cấp đủ dưỡng chất giúp duy trì năng lượng và phục hồi sức khỏe. Dùng 1 lần với dây nuôi ăn, hạn chế nhiễm khuẩn so với pha sữa bột. | F229: =IFERROR(INDEX(Brand!$A:$A,MATCH(TRIM(C229),Brand!$B:$B,0)),"NOT FOUND") -> BRAND-044 | G229: túi | H229: ="INSERT INTO medical_supply_product (active, category, description, name, code, brand_code, uom) VALUES (true, '"&SUBSTITUTE(D229,"'","''")&"', '"&SUBSTITUTE(E229,"'","''")&"', '"&SUBSTITUTE(B229,"'","''")&"', '"&SUBSTITUTE(A229,"'","''")&"', '"&SUBSTITUTE(F229,"'","''")&"', '"&SUBSTITUTE(G229,"'","''")&"');" -> INSERT INTO medical_supply_product (active, category, description, name, code, brand_code, uom) VALUES (true, 'Sữa dinh dưỡng', 'Sữa Nutrison (Nutricia) dạng nước dùng nuôi ăn qua ống thông dạ dày, cung cấp đủ dưỡng chất giúp duy trì năng lượng và phục hồi sức khỏe. Dùng 1 lần với dây nuôi ăn, hạn chế nhiễm khuẩn so với pha sữa bột.', '[Nutricia] Sữa dinh dưỡng nuôi ăn qua ống thông - Nutrison (1000ml)', 'PRODUCT-00228', 'BRAND-044', 'túi');
A230: PRODUCT-00229 | B230: [SeaSight] Bộ mở dạ dày qua da | C230: SeaSight | D230: Bộ mở thông dạ dày qua da | E230: Bộ mở thông dạ dày qua da SeaSight bằng silicone, nuôi ăn qua thành bụng cho người tắc nghẽn tiêu hóa, tai biến, chấn thương đầu cổ. Ống 3 nòng: cổng bơm thức ăn, cổng bơm thuốc và cổng van bơm bóng cố định. | F230: =IFERROR(INDEX(Brand!$A:$A,MATCH(TRIM(C230),Brand!$B:$B,0)),"NOT FOUND") -> BRAND-054 | G230: cái | H230: ="INSERT INTO medical_supply_product (active, category, description, name, code, brand_code, uom) VALUES (true, '"&SUBSTITUTE(D230,"'","''")&"', '"&SUBSTITUTE(E230,"'","''")&"', '"&SUBSTITUTE(B230,"'","''")&"', '"&SUBSTITUTE(A230,"'","''")&"', '"&SUBSTITUTE(F230,"'","''")&"', '"&SUBSTITUTE(G230,"'","''")&"');" -> INSERT INTO medical_supply_product (active, category, description, name, code, brand_code, uom) VALUES (true, 'Bộ mở thông dạ dày qua da', 'Bộ mở thông dạ dày qua da SeaSight bằng silicone, nuôi ăn qua thành bụng cho người tắc nghẽn tiêu hóa, tai biến, chấn thương đầu cổ. Ống 3 nòng: cổng bơm thức ăn, cổng bơm thuốc và cổng van bơm bóng cố định.', '[SeaSight] Bộ mở dạ dày qua da', 'PRODUCT-00229', 'BRAND-054', 'cái');
A231: PRODUCT-00230 | B231: [SeaSight] Dây nuôi ăn mũi - dạ dày silicone dài ngày | C231: SeaSight | D231: Ống thông nuôi ăn | E231: Dây nuôi ăn mũi - dạ dày silicone Seasight (1000mm) lưu ống đến 29 ngày, dùng đưa dinh dưỡng, thuốc vào dạ dày hoặc rửa, giảm áp dạ dày. Ít phải thay ống, giảm tổn thương mũi họng; tiệt trùng EO. | F231: =IFERROR(INDEX(Brand!$A:$A,MATCH(TRIM(C231),Brand!$B:$B,0)),"NOT FOUND") -> BRAND-054 | G231: cái | H231: ="INSERT INTO medical_supply_product (active, category, description, name, code, brand_code, uom) VALUES (true, '"&SUBSTITUTE(D231,"'","''")&"', '"&SUBSTITUTE(E231,"'","''")&"', '"&SUBSTITUTE(B231,"'","''")&"', '"&SUBSTITUTE(A231,"'","''")&"', '"&SUBSTITUTE(F231,"'","''")&"', '"&SUBSTITUTE(G231,"'","''")&"');" -> INSERT INTO medical_supply_product (active, category, description, name, code, brand_code, uom) VALUES (true, 'Ống thông nuôi ăn', 'Dây nuôi ăn mũi - dạ dày silicone Seasight (1000mm) lưu ống đến 29 ngày, dùng đưa dinh dưỡng, thuốc vào dạ dày hoặc rửa, giảm áp dạ dày. Ít phải thay ống, giảm tổn thương mũi họng; tiệt trùng EO.', '[SeaSight] Dây nuôi ăn mũi - dạ dày silicone dài ngày', 'PRODUCT-00230', 'BRAND-054', 'cái');
A232: PRODUCT-00231 | B232: [Teleflex] Ống chẹn thực quản, dạ dày - Sengstaken-Blakemore Tube | C232: Teleflex | D232: Ống chẹn thực quản dạ dày | E232: Ống chẹn thực quản - dạ dày Sengstaken-Blakemore (Teleflex RÜSCH) dùng cầm máu tạm thời khi chảy máu thực quản cấp (thường do xơ gan) trong lúc chờ điều trị triệt để. Ống 3–4 nòng có bóng chèn tại vị trí chảy máu ở thực quản hoặc dạ dày. | F232: =IFERROR(INDEX(Brand!$A:$A,MATCH(TRIM(C232),Brand!$B:$B,0)),"NOT FOUND") -> BRAND-060 | G232: cái | H232: ="INSERT INTO medical_supply_product (active, category, description, name, code, brand_code, uom) VALUES (true, '"&SUBSTITUTE(D232,"'","''")&"', '"&SUBSTITUTE(E232,"'","''")&"', '"&SUBSTITUTE(B232,"'","''")&"', '"&SUBSTITUTE(A232,"'","''")&"', '"&SUBSTITUTE(F232,"'","''")&"', '"&SUBSTITUTE(G232,"'","''")&"');" -> INSERT INTO medical_supply_product (active, category, description, name, code, brand_code, uom) VALUES (true, 'Ống chẹn thực quản dạ dày', 'Ống chẹn thực quản - dạ dày Sengstaken-Blakemore (Teleflex RÜSCH) dùng cầm máu tạm thời khi chảy máu thực quản cấp (thường do xơ gan) trong lúc chờ điều trị triệt để. Ống 3–4 nòng có bóng chèn tại vị trí chảy máu ở thực quản hoặc dạ dày.', '[Teleflex] Ống chẹn thực quản, dạ dày - Sengstaken-Blakemore Tube', 'PRODUCT-00231', 'BRAND-060', 'cái');
... A301: PRODUCT-00300 | B301: [Hollister] Vòng bảo vệ da chống loét hậu môn nhân tạo (Mẫu 7806) | C301: Hollister | D301: Phụ kiện hậu môn nhân tạo | E301: Vòng bảo vệ da Hollister 7805 dùng keo Flextend M bám chắc, tạo hàng rào chống thấm quanh hậu môn nhân tạo. Lấp khoảng hở, ngăn chất thải tiếp xúc da, giảm kích ứng và loét. | F301: =IFERROR(INDEX(Brand!$A:$A,MATCH(TRIM(C301),Brand!$B:$B,0)),"NOT FOUND") -> BRAND-024 | G301: cái | H301: ="INSERT INTO medical_supply_product (active, category, description, name, code, brand_code, uom) VALUES (true, '"&SUBSTITUTE(D301,"'","''")&"', '"&SUBSTITUTE(E301,"'","''")&"', '"&SUBSTITUTE(B301,"'","''")&"', '"&SUBSTITUTE(A301,"'","''")&"', '"&SUBSTITUTE(F301,"'","''")&"', '"&SUBSTITUTE(G301,"'","''")&"');" -> INSERT INTO medical_supply_product (active, category, description, name, code, brand_code, uom) VALUES (true, 'Phụ kiện hậu môn nhân tạo', 'Vòng bảo vệ da Hollister 7805 dùng keo Flextend M bám chắc, tạo hàng rào chống thấm quanh hậu môn nhân tạo. Lấp khoảng hở, ngăn chất thải tiếp xúc da, giảm kích ứng và loét.', '[Hollister] Vòng bảo vệ da chống loét hậu môn nhân tạo (Mẫu 7806)', 'PRODUCT-00300', 'BRAND-024', 'cái');

Sheet Product Variant
A1: Mã biến thể | B1: Mã sản phẩm | C1: Tên sản phẩm (rút gọn) | D1: Thông tin bổ sung | E1: INSERT INTO public.medical_supply_product_variant (id, additional_desc, code, color, size, product_code) VALUES (1, '11', '1', '11', '111', 'PRODUCT-00062');
A2: =B2&"-"&TEXT(COUNTIF(B$2:B2,B2),"000") -> PRODUCT-00001-001 | B2: PRODUCT-00001 | C2: =IFERROR(INDEX(Product!$B:$B,MATCH(B2,Product!$A:$A,0)),"NOT FOUND") -> [Greetmed] Phao chống loét cao su | E2: ="INSERT INTO public.medical_supply_product_variant (additional_desc, code, product_code) VALUES ("&IF(D2="","NULL","'"&SUBSTITUTE(D2,"'","''")&"'")&", '"&A2&"', '"&B2&"');" -> INSERT INTO public.medical_supply_product_variant (additional_desc, code, product_code) VALUES (NULL, 'PRODUCT-00001-001', 'PRODUCT-00001');
A3: =B3&"-"&TEXT(COUNTIF(B$2:B3,B3),"000") -> PRODUCT-00002-001 | B3: PRODUCT-00002 | C3: =IFERROR(INDEX(Product!$B:$B,MATCH(B3,Product!$A:$A,0)),"NOT FOUND") -> [iMedicare] Đệm hơi chống lở loét - iAM-8P | E3: ="INSERT INTO public.medical_supply_product_variant (additional_desc, code, product_code) VALUES ("&IF(D3="","NULL","'"&SUBSTITUTE(D3,"'","''")&"'")&", '"&A3&"', '"&B3&"');" -> INSERT INTO public.medical_supply_product_variant (additional_desc, code, product_code) VALUES (NULL, 'PRODUCT-00002-001', 'PRODUCT-00002');
A4: =B4&"-"&TEXT(COUNTIF(B$2:B4,B4),"000") -> PRODUCT-00003-001 | B4: PRODUCT-00003 | C4: =IFERROR(INDEX(Product!$B:$B,MATCH(B4,Product!$A:$A,0)),"NOT FOUND") -> [Lucass] Đệm hơi chống lở loét - LC-389 | E4: ="INSERT INTO public.medical_supply_product_variant (additional_desc, code, product_code) VALUES ("&IF(D4="","NULL","'"&SUBSTITUTE(D4,"'","''")&"'")&", '"&A4&"', '"&B4&"');" -> INSERT INTO public.medical_supply_product_variant (additional_desc, code, product_code) VALUES (NULL, 'PRODUCT-00003-001', 'PRODUCT-00003');
A5: =B5&"-"&TEXT(COUNTIF(B$2:B5,B5),"000") -> PRODUCT-00004-001 | B5: PRODUCT-00004 | C5: =IFERROR(INDEX(Product!$B:$B,MATCH(B5,Product!$A:$A,0)),"NOT FOUND") -> [Rionet] Máy trợ thính có dây đeo - HA-20DX | E5: ="INSERT INTO public.medical_supply_product_variant (additional_desc, code, product_code) VALUES ("&IF(D5="","NULL","'"&SUBSTITUTE(D5,"'","''")&"'")&", '"&A5&"', '"&B5&"');" -> INSERT INTO public.medical_supply_product_variant (additional_desc, code, product_code) VALUES (NULL, 'PRODUCT-00004-001', 'PRODUCT-00004');
A6: =B6&"-"&TEXT(COUNTIF(B$2:B6,B6),"000") -> PRODUCT-00005-001 | B6: PRODUCT-00005 | C6: =IFERROR(INDEX(Product!$B:$B,MATCH(B6,Product!$A:$A,0)),"NOT FOUND") -> [Rionet] Máy trợ thính không dây - HB-23P | E6: ="INSERT INTO public.medical_supply_product_variant (additional_desc, code, product_code) VALUES ("&IF(D6="","NULL","'"&SUBSTITUTE(D6,"'","''")&"'")&", '"&A6&"', '"&B6&"');" -> INSERT INTO public.medical_supply_product_variant (additional_desc, code, product_code) VALUES (NULL, 'PRODUCT-00005-001', 'PRODUCT-00005');
A7: =B7&"-"&TEXT(COUNTIF(B$2:B7,B7),"000") -> PRODUCT-00006-001 | B7: PRODUCT-00006 | C7: =IFERROR(INDEX(Product!$B:$B,MATCH(B7,Product!$A:$A,0)),"NOT FOUND") -> [Rionet] Máy trợ thính không dây thông minh - HM-06 | E7: ="INSERT INTO public.medical_supply_product_variant (additional_desc, code, product_code) VALUES ("&IF(D7="","NULL","'"&SUBSTITUTE(D7,"'","''")&"'")&", '"&A7&"', '"&B7&"');" -> INSERT INTO public.medical_supply_product_variant (additional_desc, code, product_code) VALUES (NULL, 'PRODUCT-00006-001', 'PRODUCT-00006');
A8: =B8&"-"&TEXT(COUNTIF(B$2:B8,B8),"000") -> PRODUCT-00007-001 | B8: PRODUCT-00007 | C8: =IFERROR(INDEX(Product!$B:$B,MATCH(B8,Product!$A:$A,0)),"NOT FOUND") -> [WaterJet] Máy tăm nước - Cordless Maxi | E8: ="INSERT INTO public.medical_supply_product_variant (additional_desc, code, product_code) VALUES ("&IF(D8="","NULL","'"&SUBSTITUTE(D8,"'","''")&"'")&", '"&A8&"', '"&B8&"');" -> INSERT INTO public.medical_supply_product_variant (additional_desc, code, product_code) VALUES (NULL, 'PRODUCT-00007-001', 'PRODUCT-00007');
A9: =B9&"-"&TEXT(COUNTIF(B$2:B9,B9),"000") -> PRODUCT-00008-001 | B9: PRODUCT-00008 | C9: =IFERROR(INDEX(Product!$B:$B,MATCH(B9,Product!$A:$A,0)),"NOT FOUND") -> [Young Chemical Vina] Miếng dán mụn - Somaderm Spot S (32 miếng) | E9: ="INSERT INTO public.medical_supply_product_variant (additional_desc, code, product_code) VALUES ("&IF(D9="","NULL","'"&SUBSTITUTE(D9,"'","''")&"'")&", '"&A9&"', '"&B9&"');" -> INSERT INTO public.medical_supply_product_variant (additional_desc, code, product_code) VALUES (NULL, 'PRODUCT-00008-001', 'PRODUCT-00008');
A10: =B10&"-"&TEXT(COUNTIF(B$2:B10,B10),"000") -> PRODUCT-00250-001 | B10: PRODUCT-00250 | C10: =IFERROR(INDEX(Product!$B:$B,MATCH(B10,Product!$A:$A,0)),"NOT FOUND") -> [Young Chemical Vina] Miếng dán mụn - Somaderm Spot (24 miếng) | E10: ="INSERT INTO public.medical_supply_product_variant (additional_desc, code, product_code) VALUES ("&IF(D10="","NULL","'"&SUBSTITUTE(D10,"'","''")&"'")&", '"&A10&"', '"&B10&"');" -> INSERT INTO public.medical_supply_product_variant (additional_desc, code, product_code) VALUES (NULL, 'PRODUCT-00250-001', 'PRODUCT-00250');
A11: =B11&"-"&TEXT(COUNTIF(B$2:B11,B11),"000") -> PRODUCT-00251-001 | B11: PRODUCT-00251 | C11: =IFERROR(INDEX(Product!$B:$B,MATCH(B11,Product!$A:$A,0)),"NOT FOUND") -> [Young Chemical Vina] Miếng dán mụn - Somaderm Spot (18 miếng) | E11: ="INSERT INTO public.medical_supply_product_variant (additional_desc, code, product_code) VALUES ("&IF(D11="","NULL","'"&SUBSTITUTE(D11,"'","''")&"'")&", '"&A11&"', '"&B11&"');" -> INSERT INTO public.medical_supply_product_variant (additional_desc, code, product_code) VALUES (NULL, 'PRODUCT-00251-001', 'PRODUCT-00251');
A12: =B12&"-"&TEXT(COUNTIF(B$2:B12,B12),"000") -> PRODUCT-00009-001 | B12: PRODUCT-00009 | C12: =IFERROR(INDEX(Product!$B:$B,MATCH(B12,Product!$A:$A,0)),"NOT FOUND") -> [Young Chemical Vina] Miếng dán mụn - Somaderm-Thin (Ø10mm) | E12: ="INSERT INTO public.medical_supply_product_variant (additional_desc, code, product_code) VALUES ("&IF(D12="","NULL","'"&SUBSTITUTE(D12,"'","''")&"'")&", '"&A12&"', '"&B12&"');" -> INSERT INTO public.medical_supply_product_variant (additional_desc, code, product_code) VALUES (NULL, 'PRODUCT-00009-001', 'PRODUCT-00009');
A13: =B13&"-"&TEXT(COUNTIF(B$2:B13,B13),"000") -> PRODUCT-00010-001 | B13: PRODUCT-00010 | C13: =IFERROR(INDEX(Product!$B:$B,MATCH(B13,Product!$A:$A,0)),"NOT FOUND") -> Mặt nạ xông hơi mắt ngải cứu - Mugwort Steam Eyes Mask | E13: ="INSERT INTO public.medical_supply_product_variant (additional_desc, code, product_code) VALUES ("&IF(D13="","NULL","'"&SUBSTITUTE(D13,"'","''")&"'")&", '"&A13&"', '"&B13&"');" -> INSERT INTO public.medical_supply_product_variant (additional_desc, code, product_code) VALUES (NULL, 'PRODUCT-00010-001', 'PRODUCT-00010');
... A95: =B95&"-"&TEXT(COUNTIF(B$2:B95,B95),"000") -> PRODUCT-00052-001 | B95: PRODUCT-00052 | C95: =IFERROR(INDEX(Product!$B:$B,MATCH(B95,Product!$A:$A,0)),"NOT FOUND") -> [CODY Health] Đai đầu gối tập luyện thể thao | E95: ="INSERT INTO public.medical_supply_product_variant (additional_desc, code, product_code) VALUES ("&IF(D95="","NULL","'"&SUBSTITUTE(D95,"'","''")&"'")&", '"&A95&"', '"&B95&"');" -> INSERT INTO public.medical_supply_product_variant (additional_desc, code, product_code) VALUES (NULL, 'PRODUCT-00052-001', 'PRODUCT-00052');
A96: =B96&"-"&TEXT(COUNTIF(B$2:B96,B96),"000") -> PRODUCT-00053-001 | B96: PRODUCT-00053 | C96: =IFERROR(INDEX(Product!$B:$B,MATCH(B96,Product!$A:$A,0)),"NOT FOUND") -> [CODY Health] Đai lưng cố định cột sống | D96: Số đo vòng bụng: 56 - 71 cm Chiều cao đai: 22 cm | E96: ="INSERT INTO public.medical_supply_product_variant (additional_desc, code, product_code) VALUES ("&IF(D96="","NULL","'"&SUBSTITUTE(D96,"'","''")&"'")&", '"&A96&"', '"&B96&"');" -> INSERT INTO public.medical_supply_product_variant (additional_desc, code, product_code) VALUES ('Số đo vòng bụng: 56 - 71 cm Chiều cao đai: 22 cm', 'PRODUCT-00053-001', 'PRODUCT-00053');
A97: =B97&"-"&TEXT(COUNTIF(B$2:B97,B97),"000") -> PRODUCT-00053-002 | B97: PRODUCT-00053 | C97: =IFERROR(INDEX(Product!$B:$B,MATCH(B97,Product!$A:$A,0)),"NOT FOUND") -> [CODY Health] Đai lưng cố định cột sống | D97: Số đo vòng bụng: 71 - 84 cm Chiều cao đai: 22 cm | E97: ="INSERT INTO public.medical_supply_product_variant (additional_desc, code, product_code) VALUES ("&IF(D97="","NULL","'"&SUBSTITUTE(D97,"'","''")&"'")&", '"&A97&"', '"&B97&"');" -> INSERT INTO public.medical_supply_product_variant (additional_desc, code, product_code) VALUES ('Số đo vòng bụng: 71 - 84 cm Chiều cao đai: 22 cm', 'PRODUCT-00053-002', 'PRODUCT-00053');
A98: =B98&"-"&TEXT(COUNTIF(B$2:B98,B98),"000") -> PRODUCT-00053-003 | B98: PRODUCT-00053 | C98: =IFERROR(INDEX(Product!$B:$B,MATCH(B98,Product!$A:$A,0)),"NOT FOUND") -> [CODY Health] Đai lưng cố định cột sống | D98: Số đo vòng bụng: 84 - 97 cm Chiều cao đai: 22 cm | E98: ="INSERT INTO public.medical_supply_product_variant (additional_desc, code, product_code) VALUES ("&IF(D98="","NULL","'"&SUBSTITUTE(D98,"'","''")&"'")&", '"&A98&"', '"&B98&"');" -> INSERT INTO public.medical_supply_product_variant (additional_desc, code, product_code) VALUES ('Số đo vòng bụng: 84 - 97 cm Chiều cao đai: 22 cm', 'PRODUCT-00053-003', 'PRODUCT-00053');
A99: =B99&"-"&TEXT(COUNTIF(B$2:B99,B99),"000") -> PRODUCT-00053-004 | B99: PRODUCT-00053 | C99: =IFERROR(INDEX(Product!$B:$B,MATCH(B99,Product!$A:$A,0)),"NOT FOUND") -> [CODY Health] Đai lưng cố định cột sống | D99: Số đo vòng bụng: 97 - 109 cm Chiều cao đai: 22 cm | E99: ="INSERT INTO public.medical_supply_product_variant (additional_desc, code, product_code) VALUES ("&IF(D99="","NULL","'"&SUBSTITUTE(D99,"'","''")&"'")&", '"&A99&"', '"&B99&"');" -> INSERT INTO public.medical_supply_product_variant (additional_desc, code, product_code) VALUES ('Số đo vòng bụng: 97 - 109 cm Chiều cao đai: 22 cm', 'PRODUCT-00053-004', 'PRODUCT-00053');
A100: =B100&"-"&TEXT(COUNTIF(B$2:B100,B100),"000") -> PRODUCT-00054-001 | B100: PRODUCT-00054 | C100: =IFERROR(INDEX(Product!$B:$B,MATCH(B100,Product!$A:$A,0)),"NOT FOUND") -> [CODY Health] Vớ đùi y khoa giãn tĩnh mạch có silicone chống trượt | D100: Vòng 1: cổ chân, ngay trên xương mắt cá chân 1cm: 18-20 cm Vòng 2: bắp chân, tại nơi lớn nhất: 31-35 cm Vòng 3: đùi, dưới bẹn 5cm: 45-53 cm Chiều dài từ bàn chân đến vòng 3: 66-76 cm | E100: ="INSERT INTO public.medical_supply_product_variant (additional_desc, code, product_code) VALUES ("&IF(D100="","NULL","'"&SUBSTITUTE(D100,"'","''")&"'")&", '"&A100&"', '"&B100&"');" -> INSERT INTO public.medical_supply_product_variant (additional_desc, code, product_code) VALUES ('Vòng 1: cổ chân, ngay trên xương mắt cá chân 1cm: 18-20 cm Vòng 2: bắp chân, tại nơi lớn nhất: 31-35 cm Vòng 3: đùi, dưới bẹn 5cm: 45-53 cm Chiều dài từ bàn chân đến vòng 3: 66-76 cm', 'PRODUCT-00054-001', 'PRODUCT-00054');
A101: =B101&"-"&TEXT(COUNTIF(B$2:B101,B101),"000") -> PRODUCT-00054-002 | B101: PRODUCT-00054 | C101: =IFERROR(INDEX(Product!$B:$B,MATCH(B101,Product!$A:$A,0)),"NOT FOUND") -> [CODY Health] Vớ đùi y khoa giãn tĩnh mạch có silicone chống trượt | D101: Vòng 1: cổ chân, ngay trên xương mắt cá chân 1cm: 20-22 cm Vòng 2: bắp chân, tại nơi lớn nhất: 33-38 cm Vòng 3: đùi, dưới bẹn 5cm: 48-56 cm Chiều dài từ bàn chân đến vòng 3: 66-76 cm | E101: ="INSERT INTO public.medical_supply_product_variant (additional_desc, code, product_code) VALUES ("&IF(D101="","NULL","'"&SUBSTITUTE(D101,"'","''")&"'")&", '"&A101&"', '"&B101&"');" -> INSERT INTO public.medical_supply_product_variant (additional_desc, code, product_code) VALUES ('Vòng 1: cổ chân, ngay trên xương mắt cá chân 1cm: 20-22 cm Vòng 2: bắp chân, tại nơi lớn nhất: 33-38 cm Vòng 3: đùi, dưới bẹn 5cm: 48-56 cm Chiều dài từ bàn chân đến vòng 3: 66-76 cm', 'PRODUCT-00054-002', 'PRODUCT-00054');
A102: =B102&"-"&TEXT(COUNTIF(B$2:B102,B102),"000") -> PRODUCT-00054-003 | B102: PRODUCT-00054 | C102: =IFERROR(INDEX(Product!$B:$B,MATCH(B102,Product!$A:$A,0)),"NOT FOUND") -> [CODY Health] Vớ đùi y khoa giãn tĩnh mạch có silicone chống trượt | D102: Vòng 1: cổ chân, ngay trên xương mắt cá chân 1cm: 22-24 cm Vòng 2: bắp chân, tại nơi lớn nhất: 34-40 cm Vòng 3: đùi, dưới bẹn 5cm: 51-59 cm Chiều dài từ bàn chân đến vòng 3: 70-80 cm | E102: ="INSERT INTO public.medical_supply_product_variant (additional_desc, code, product_code) VALUES ("&IF(D102="","NULL","'"&SUBSTITUTE(D102,"'","''")&"'")&", '"&A102&"', '"&B102&"');" -> INSERT INTO public.medical_supply_product_variant (additional_desc, code, product_code) VALUES ('Vòng 1: cổ chân, ngay trên xương mắt cá chân 1cm: 22-24 cm Vòng 2: bắp chân, tại nơi lớn nhất: 34-40 cm Vòng 3: đùi, dưới bẹn 5cm: 51-59 cm Chiều dài từ bàn chân đến vòng 3: 70-80 cm', 'PRODUCT-00054-003', 'PRODUCT-00054');
A103: =B103&"-"&TEXT(COUNTIF(B$2:B103,B103),"000") -> PRODUCT-00055-001 | B103: PRODUCT-00055 | C103: =IFERROR(INDEX(Product!$B:$B,MATCH(B103,Product!$A:$A,0)),"NOT FOUND") -> [CODY Health] Vớ gối y khoa giãn tĩnh mạch | D103: Vòng 1: cổ chân, ngay trên xương mắt cá chân 1cm: 18-20 cm Vòng 2: bắp chân, tại nơi lớn nhất: 31-35 cm Chiều dài từ bàn chân đến đoạn dưới gối: 66-76 cm | E103: ="INSERT INTO public.medical_supply_product_variant (additional_desc, code, product_code) VALUES ("&IF(D103="","NULL","'"&SUBSTITUTE(D103,"'","''")&"'")&", '"&A103&"', '"&B103&"');" -> INSERT INTO public.medical_supply_product_variant (additional_desc, code, product_code) VALUES ('Vòng 1: cổ chân, ngay trên xương mắt cá chân 1cm: 18-20 cm Vòng 2: bắp chân, tại nơi lớn nhất: 31-35 cm Chiều dài từ bàn chân đến đoạn dưới gối: 66-76 cm', 'PRODUCT-00055-001', 'PRODUCT-00055');
A104: =B104&"-"&TEXT(COUNTIF(B$2:B104,B104),"000") -> PRODUCT-00055-002 | B104: PRODUCT-00055 | C104: =IFERROR(INDEX(Product!$B:$B,MATCH(B104,Product!$A:$A,0)),"NOT FOUND") -> [CODY Health] Vớ gối y khoa giãn tĩnh mạch | D104: Vòng 1: cổ chân, ngay trên xương mắt cá chân 1cm: 20-22 cm Vòng 2: bắp chân, tại nơi lớn nhất: 33-38 cm Chiều dài từ bàn chân đến đoạn dưới gối: 66-76 cm | E104: ="INSERT INTO public.medical_supply_product_variant (additional_desc, code, product_code) VALUES ("&IF(D104="","NULL","'"&SUBSTITUTE(D104,"'","''")&"'")&", '"&A104&"', '"&B104&"');" -> INSERT INTO public.medical_supply_product_variant (additional_desc, code, product_code) VALUES ('Vòng 1: cổ chân, ngay trên xương mắt cá chân 1cm: 20-22 cm Vòng 2: bắp chân, tại nơi lớn nhất: 33-38 cm Chiều dài từ bàn chân đến đoạn dưới gối: 66-76 cm', 'PRODUCT-00055-002', 'PRODUCT-00055');
A105: =B105&"-"&TEXT(COUNTIF(B$2:B105,B105),"000") -> PRODUCT-00055-003 | B105: PRODUCT-00055 | C105: =IFERROR(INDEX(Product!$B:$B,MATCH(B105,Product!$A:$A,0)),"NOT FOUND") -> [CODY Health] Vớ gối y khoa giãn tĩnh mạch | D105: Vòng 1: cổ chân, ngay trên xương mắt cá chân 1cm: 22-24 cm Vòng 2: bắp chân, tại nơi lớn nhất: 34-40 cm Chiều dài từ bàn chân đến đoạn dưới gối: 70-80 cm | E105: ="INSERT INTO public.medical_supply_product_variant (additional_desc, code, product_code) VALUES ("&IF(D105="","NULL","'"&SUBSTITUTE(D105,"'","''")&"'")&", '"&A105&"', '"&B105&"');" -> INSERT INTO public.medical_supply_product_variant (additional_desc, code, product_code) VALUES ('Vòng 1: cổ chân, ngay trên xương mắt cá chân 1cm: 22-24 cm Vòng 2: bắp chân, tại nơi lớn nhất: 34-40 cm Chiều dài từ bàn chân đến đoạn dưới gối: 70-80 cm', 'PRODUCT-00055-003', 'PRODUCT-00055');
A106: =B106&"-"&TEXT(COUNTIF(B$2:B106,B106),"000") -> PRODUCT-00056-001 | B106: PRODUCT-00056 | C106: =IFERROR(INDEX(Product!$B:$B,MATCH(B106,Product!$A:$A,0)),"NOT FOUND") -> [CODY Health] Vớ y khoa giãn tĩnh mạch (Vớ gối) | D106: Vòng 1: vòng cổ chân, ngay trên xương mắt cá chân 1cm: 18-20 cm Vòng 2: vòng bắp chân, tại nơi lớn nhất: 31-35 cm Vòng 3: vòng đùi, dưới bẹn 5cm: 45-53 cm | E106: ="INSERT INTO public.medical_supply_product_variant (additional_desc, code, product_code) VALUES ("&IF(D106="","NULL","'"&SUBSTITUTE(D106,"'","''")&"'")&", '"&A106&"', '"&B106&"');" -> INSERT INTO public.medical_supply_product_variant (additional_desc, code, product_code) VALUES ('Vòng 1: vòng cổ chân, ngay trên xương mắt cá chân 1cm: 18-20 cm Vòng 2: vòng bắp chân, tại nơi lớn nhất: 31-35 cm Vòng 3: vòng đùi, dưới bẹn 5cm: 45-53 cm', 'PRODUCT-00056-001', 'PRODUCT-00056');
A107: =B107&"-"&TEXT(COUNTIF(B$2:B107,B107),"000") -> PRODUCT-00056-002 | B107: PRODUCT-00056 | C107: =IFERROR(INDEX(Product!$B:$B,MATCH(B107,Product!$A:$A,0)),"NOT FOUND") -> [CODY Health] Vớ y khoa giãn tĩnh mạch (Vớ gối) | D107: Vòng 1: vòng cổ chân, ngay trên xương mắt cá chân 1cm: 20-22 cm Vòng 2: vòng bắp chân, tại nơi lớn nhất: 33-38 cm Vòng 3: vòng đùi, dưới bẹn 5cm: 48-56 cm | E107: ="INSERT INTO public.medical_supply_product_variant (additional_desc, code, product_code) VALUES ("&IF(D107="","NULL","'"&SUBSTITUTE(D107,"'","''")&"'")&", '"&A107&"', '"&B107&"');" -> INSERT INTO public.medical_supply_product_variant (additional_desc, code, product_code) VALUES ('Vòng 1: vòng cổ chân, ngay trên xương mắt cá chân 1cm: 20-22 cm Vòng 2: vòng bắp chân, tại nơi lớn nhất: 33-38 cm Vòng 3: vòng đùi, dưới bẹn 5cm: 48-56 cm', 'PRODUCT-00056-002', 'PRODUCT-00056');
... A111: =B111&"-"&TEXT(COUNTIF(B$2:B111,B111),"000") -> PRODUCT-00296-003 | B111: PRODUCT-00296 | C111: =IFERROR(INDEX(Product!$B:$B,MATCH(B111,Product!$A:$A,0)),"NOT FOUND") -> [CODY Health] Vớ y khoa giãn tĩnh mạch (Vớ đùi) | D111: Vòng 1: vòng cổ chân, ngay trên xương mắt cá chân 1cm: 22-24 cm Vòng 2: vòng bắp chân, tại nơi lớn nhất: 34-40 cm Vòng 3: vòng đùi, dưới bẹn 5cm: 51-59 cm | E111: ="INSERT INTO public.medical_supply_product_variant (additional_desc, code, product_code) VALUES ("&IF(D111="","NULL","'"&SUBSTITUTE(D111,"'","''")&"'")&", '"&A111&"', '"&B111&"');" -> INSERT INTO public.medical_supply_product_variant (additional_desc, code, product_code) VALUES ('Vòng 1: vòng cổ chân, ngay trên xương mắt cá chân 1cm: 22-24 cm Vòng 2: vòng bắp chân, tại nơi lớn nhất: 34-40 cm Vòng 3: vòng đùi, dưới bẹn 5cm: 51-59 cm', 'PRODUCT-00296-003', 'PRODUCT-00296');
